Workbook

Sheet Допущения
B2: План продаж | N2: Структура себестоимости* | S2: Прочие вводные данные
B4: Год | D4: Ед. изм. | E4: 2023 | F4: 2024 | G4: 2025 | H4: 2026 | I4: 2027 | J4: 2028 | L4: 2029 | N4: Год | P4: Ед. изм. | Q4: Значение | S4: Показатель | W4: Ед. изм. | X4: Значение
B5: Ежегодный прирост | D5: % | E5: 0.2 | F5: 0.18 | G5: 0.15 | H5: 0.1 | I5: 0.07 | J5: 0.05 | L5: 0.03 | N5: ТМЦ | P5: % | Q5: 0.755 | S5: Минимальный остаток денежных средств | W5: млн руб. | X5: 1000
B6: Валовая маржинальность* | D6: % | E6: 0.24 | F6: 0.25 | G6: 0.25 | H6: 0.25 | I6: 0.25 | J6: 0.25 | L6: 0.25 | N6: Оплата труда | P6: % | Q6: 0.08 | S6: Срок кредитования | W6: лет | X6: 2
B7: Доля онлайн-продаж | D7: % | E7: 0.04 | F7: 0.05 | G7: 0.06 | H7: 0.08 | I7: 0.1 | J7: 0.12 | L7: 0.12 | N7: Прочее | P7: % | Q7: =1-Q5-Q6 -> 0.165 | S7: Доля финансирования запасов | W7: % | X7: 0.6
B8: *Без учета амортизации | N8: Итого: | P8: % | Q8: =SUM(Q5:Q7) -> 1
N9: *Без учета амортизации
B11: Инвестиции (в текущих ценах)
B13: Год | D13: Ед. изм. | E13: 2023 | F13: 2024 | G13: 2025 | H13: 2026 | I13: 2027 | J13: 2028 | L13: 2029
B14: Недвижимость | D14: млн руб. | E14: 130325 | F14: 120000 | G14: 110000 | H14: 100000 | I14: 80000 | J14: 60000 | L14: 40000
B17: Макроэкономика
B19: Год | D19: Ед. изм. | E19: 2023 | F19: 2024 | G19: 2025 | H19: 2026 | I19: 2027 | J19: 2028 | L19: 2029
B20: Инфляция | D20: % | F20: 0.09 | G20: 0.06 | H20: 0.04 | I20: 0.04 | J20: 0.04 | L20: 0.04
B21: Проценты по депозитам | D21: % | F21: 0.15 | G21: 0.14 | H21: 0.12 | I21: 0.1 | J21: 0.05 | L21: 0.05
B22: Ставка кредитования | D22: % | E22: 0.15 | F22: 0.2 | G22: 0.19 | H22: 0.15 | I22: 0.1 | J22: 0.08 | L22: 0.08
B23: Налог на прибыль | E23: 0.2 | F23: 0.2 | G23: 0.2 | H23: 0.2 | I23: 0.2 | J23: 0.2 | L23: 0.2
B24: Курс доллара | E24: 85 | F24: 92 | G24: 83 | H24: 92 | I24: 96 | J24: 100 | L24: 110
B27: Планируемая кредиторская задолженность | N27: Сценарии по КЗ
B29: Показатель | D29: Ед. изм. | E29: 0 | F29: 1 | G29: 2 | H29: 3 | I29: 4 | J29: 5 | L29: 6 | N29: Выбор сценария | Q29: 1
B30: Всего КЗ | D30: млн руб. | E30: 1 | F30: 1 | G30: 1 | H30: 1 | I30: 1 | J30: 1 | L30: 1
B31: Доля поставщиков | C31: =HLOOKUP($Q$29,$O$31:$Q$33,3,0) -> 0.15 | N31: Сценарий | O31: 1 | P31: 2 | Q31: 3
B32: Получение аванса | C32: =HLOOKUP($Q$29,$O$31:$Q$33,2,0) -> 0.8 | D32: млн руб. | E32: =E30*$C$32 -> 0.8 | F32: =F30*$C$32 -> 0.8 | G32: =G30*$C$32 -> 0.8 | H32: =H30*$C$32 -> 0.8 | I32: =I30*$C$32 -> 0.8 | J32: =J30*$C$32 -> 0.8 | L32: =L30*$C$32 -> 0.8 | N32: Аванс | O32: 0.8 | P32: 0.7 | Q32: 0.2
B33: Погашение задолженности | C33: 0.8 | D33: млн руб. | E33: =E30-E32 -> 0.2 | F33: =F30-F32 -> 0.2 | G33: =G30-G32 -> 0.2 | H33: =H30-H32 -> 0.2 | I33: =I30-I32 -> 0.2 | J33: =J30-J32 -> 0.2 | L33: =L30-L32 -> 0.2 | N33: Процент | O33: 0.15 | P33: 0.2 | Q33: 0.2
B35: Основные средства (ОС) и нематериальные активы (НМА)
B37: Типы основных средств | D37: Ед. изм. | E37: Первонач. стоимость | F37: Остаточ. стоимость | G37: Аморти-зация | H37: Общий срок амортиз. | I37: Остаточ. срок амортиз. | J37: Доля в инвести-циях
B38: Земельные участки и здания | D38: млн руб. | E38: 371990 | F38: 186645 | G38: -185345 | H38: 30 | I38: 7 | J38: 0.27
B39: Машины и оборудование | D39: млн руб. | E39: 109176 | F39: 54191 | G39: -54985 | H39: 5 | I39: 3 | J39: 0.27
B40: Холодильное оборудование | D40: млн руб. | E40: 92145 | F40: 38596 | G40: -53549 | H40: 8 | I40: 3 | J40: 0.1
B41: Транспортные средства | D41: млн руб. | E41: 41628 | F41: 20652 | G41: -20976 | H41: 6 | I41: =ROUNDUP(F41/E41*H41,0) -> 3 | J41: 0.1
B42: Прочее | D42: млн руб. | E42: 90295 | F42: 28156 | G42: -62139 | H42: 3 | I42: 2 | J42: 0.16
B43: Незавершенное строительство | D43: млн руб. | E43: 36197 | F43: 36151 | H43: 5 | I43: =ROUNDUP(F43/E43*H43,0) -> 5
B44: НМА | D44: млн руб. | E44: 95243 | F44: 40750 | G44: -54493 | H44: 10 | I44: 4 | J44: 0.1
B52: Источник: годовой отчет за 2023 год

Sheet Расчет
B2: Период | D2: Ед. изм. | E2: 2023 | F2: 2024 | G2: 2025 | H2: 2026 | I2: 2027 | J2: 2028 | L2: 2029
B3: Дата | D3: Х | E3: =DATE(E2,12,31) -> 45291 | F3: =DATE(F2,12,31) -> 45657 | G3: =DATE(G2,12,31) -> 46022 | H3: =DATE(H2,12,31) -> 46387 | I3: =DATE(I2,12,31) -> 46752 | J3: =DATE(J2,12,31) -> 47118
B4: Этапы | D4: Х | E4: Факт | F4: План | G4: План | H4: План | I4: План | J4: План | L4: План
B5: k инфляции | D5: % | E5: 1 | F5: =E5*(1+Допущения!F$20) -> 1.09 | G5: =F5*(1+Допущения!G$20) -> 1.1554 | H5: =G5*(1+Допущения!H$20) -> 1.201616 | I5: =H5*(1+Допущения!I$20) -> 1.2496806 | J5: =I5*(1+Допущения!J$20) -> 1.2996679 | L5: =J5*(1+Допущения!L$20) -> 1.3516546
B6: k роста | D6: % | E6: 1 | F6: =E6*(1+Допущения!F$5) -> 1.18 | G6: =F6*(1+Допущения!G$5) -> 1.357 | H6: =G6*(1+Допущения!H$5) -> 1.4927 | I6: =H6*(1+Допущения!I$5) -> 1.597189 | J6: =I6*(1+Допущения!J$5) -> 1.6770485 | L6: =J6*(1+Допущения!L$5) -> 1.7273599
B8: Вспомогательные расчеты
B10: Планирование выручки
B12: Продажи продукции | D12: млн руб. | E12: 3138516.8 | F12: =E12*(1+Допущения!F$5) -> 3703449.8 | G12: =F12*(1+Допущения!G$5) -> 4258967.3 | H12: =G12*(1+Допущения!H$5) -> 4684864 | I12: =H12*(1+Допущения!I$5) -> 5012804.5 | J12: =I12*(1+Допущения!J$5) -> 5263444.8 | L12: =J12*(1+Допущения!L$5) -> 5421348.1
B14: Доля КЗ поставщикам | D14: млн руб. | E14: =E17*(1+Допущения!C32) -> 522417.6 | F14: =Допущения!$C$31*F$12 -> 555517.48 | G14: =Допущения!$C$31*G$12 -> 638845.1 | H14: =Допущения!$C$31*H$12 -> 702729.61 | I14: =Допущения!$C$31*I$12 -> 751920.68 | J14: =Допущения!$C$31*J$12 -> 789516.71 | L14: =Допущения!$C$31*L$12 -> 813202.21
B15: Аванс по КЗ | D15: млн руб. | E15: =E14*Допущения!E32 -> 417934.08 | F15: =F14*Допущения!F32 -> 444413.98 | G15: =G14*Допущения!G32 -> 511076.08 | H15: =H14*Допущения!H32 -> 562183.69 | I15: =I14*Допущения!I32 -> 601536.54 | J15: =J14*Допущения!J32 -> 631613.37 | L15: =L14*Допущения!L32 -> 650561.77
B16: Погашение КЗ | D16: млн руб. | F16: =E14-E15 -> 104483.52 | G16: =F14-F15 -> 111103.5 | H16: =G14-G15 -> 127769.02 | I16: =H14-H15 -> 140545.92 | J16: =I14-I15 -> 150384.14 | L16: =J14-J15 -> 157903.34
B17: Остаток КЗ | D17: млн руб. | E17: 290232 | F17: =E17+F14-F15-F16 -> 296851.98 | G17: =F17+G14-G15-G16 -> 313517.5 | H17: =G17+H14-H15-H16 -> 326294.4 | I17: =H17+I14-I15-I16 -> 336132.62 | J17: =I17+J14-J15-J16 -> 343651.82 | L17: =J17+L14-L15-L16 -> 348388.92
B18: Изменение КЗ | D18: млн руб. | F18: =F17-E17 -> 6619.9751 | G18: =G17-F17 -> 16665.524 | H18: =H17-G17 -> 12776.902 | I18: =I17-H17 -> 9838.2145 | J18: =J17-I17 -> 7519.2068 | L18: =L17-J17 -> 4737.1003
B19: Дебиторская задолженность | D19: млн руб. | E19: 36928 | F19: =$E$19*F5 -> 40251.52 | G19: =$E$19*G5 -> 42666.611 | H19: =$E$19*H5 -> 44373.276 | I19: =$E$19*I5 -> 46148.207 | J19: =$E$19*J5 -> 47994.135 | L19: =$E$19*L5 -> 49913.9
B20: Изменение ДЗ | D20: млн руб. | F20: =F19-E19 -> 3323.52 | G20: =G19-F19 -> 2415.0912 | H20: =H19-G19 -> 1706.6644 | I20: =I19-H19 -> 1774.931 | J20: =J19-I19 -> 1845.9283 | L20: =L19-J19 -> 1919.7654
B22: Выручка итого: | D22: млн руб. | E22: =E12 -> 3138516.8 | F22: =F12 -> 3703449.8 | G22: =G12 -> 4258967.3 | H22: =H12 -> 4684864 | I22: =I12 -> 5012804.5 | J22: =J12 -> 5263444.8 | L22: =L12 -> 5421348.1
B25: Инвестиции
B27: Инвестиции | D27: млн руб. | F27: =SUM(F28:F33) -> 130800 | G27: =SUM(G28:G33) -> 127094 | H27: =SUM(H28:H33) -> 120161.6 | I27: =SUM(I28:I33) -> 99974.451 | J27: =SUM(J28:J33) -> 77980.072 | L27: =SUM(L28:L33) -> 54066.183
B28: Здания | D28: млн руб. | F28: =Допущения!F$14*Допущения!$J38*F$5 -> 35316 | G28: =Допущения!G$14*Допущения!$J38*G$5 -> 34315.38 | H28: =Допущения!H$14*Допущения!$J38*H$5 -> 32443.632 | I28: =Допущения!I$14*Допущения!$J38*I$5 -> 26993.102 | J28: =Допущения!J$14*Допущения!$J38*J$5 -> 21054.619 | L28: =Допущения!L$14*Допущения!$J38*L$5 -> 14597.869
B29: Машины и оборудование | D29: млн руб. | F29: =Допущения!F$14*Допущения!$J39*F$5 -> 35316 | G29: =Допущения!G$14*Допущения!$J39*G$5 -> 34315.38 | H29: =Допущения!H$14*Допущения!$J39*H$5 -> 32443.632 | I29: =Допущения!I$14*Допущения!$J39*I$5 -> 26993.102 | J29: =Допущения!J$14*Допущения!$J39*J$5 -> 21054.619 | L29: =Допущения!L$14*Допущения!$J39*L$5 -> 14597.869
B30: Холодильное оборудование | D30: млн руб. | F30: =Допущения!F$14*Допущения!$J40*F$5 -> 13080 | G30: =Допущения!G$14*Допущения!$J40*G$5 -> 12709.4 | H30: =Допущения!H$14*Допущения!$J40*H$5 -> 12016.16 | I30: =Допущения!I$14*Допущения!$J40*I$5 -> 9997.4451 | J30: =Допущения!J$14*Допущения!$J40*J$5 -> 7798.0072 | L30: =Допущения!L$14*Допущения!$J40*L$5 -> 5406.6183
B31: Транспортные средства | D31: млн руб. | F31: =Допущения!F$14*Допущения!$J41*F$5 -> 13080 | G31: =Допущения!G$14*Допущения!$J41*G$5 -> 12709.4 | H31: =Допущения!H$14*Допущения!$J41*H$5 -> 12016.16 | I31: =Допущения!I$14*Допущения!$J41*I$5 -> 9997.4451 | J31: =Допущения!J$14*Допущения!$J41*J$5 -> 7798.0072 | L31: =Допущения!L$14*Допущения!$J41*L$5 -> 5406.6183
B32: Прочее | D32: млн руб. | F32: =Допущения!F$14*Допущения!$J42*F$5 -> 20928 | G32: =Допущения!G$14*Допущения!$J42*G$5 -> 20335.04 | H32: =Допущения!H$14*Допущения!$J42*H$5 -> 19225.856 | I32: =Допущения!I$14*Допущения!$J42*I$5 -> 15995.912 | J32: =Допущения!J$14*Допущения!$J42*J$5 -> 12476.812 | L32: =Допущения!L$14*Допущения!$J42*L$5 -> 8650.5893
B33: НМА | D33: млн руб. | F33: =Допущения!F$14*Допущения!$J44*F$5 -> 13080 | G33: =Допущения!G$14*Допущения!$J44*G$5 -> 12709.4 | H33: =Допущения!H$14*Допущения!$J44*H$5 -> 12016.16 | I33: =Допущения!I$14*Допущения!$J44*I$5 -> 9997.4451 | J33: =Допущения!J$14*Допущения!$J44*J$5 -> 7798.0072 | L33: =Допущения!L$14*Допущения!$J44*L$5 -> 5406.6183
B35: Первоначальная стоимость | D35: млн руб. | F35: =SUM(F36:F41) -> 130800 | G35: =SUM(G36:G41) -> 257894 | H35: =SUM(H36:H41) -> 378055.6 | I35: =SUM(I36:I41) -> 457102.05 | J35: =SUM(J36:J41) -> 514747.08 | L35: =SUM(L36:L41) -> 514271.41
B36: Здания | D36: млн руб. | F36: =SUM($F28:F28)-SUMPRODUCT((F$2-$F$2:F$2>=Допущения!$H38)*$F28:F28) -> 35316 | G36: =SUM($F28:G28)-SUMPRODUCT((G$2-$F$2:G$2>=Допущения!$H38)*$F28:G28) -> 69631.38 | H36: =SUM($F28:H28)-SUMPRODUCT((H$2-$F$2:H$2>=Допущения!$H38)*$F28:H28) -> 102075.01 | I36: =SUM($F28:I28)-SUMPRODUCT((I$2-$F$2:I$2>=Допущения!$H38)*$F28:I28) -> 129068.11 | J36: =SUM($F28:J28)-SUMPRODUCT((J$2-$F$2:J$2>=Допущения!$H38)*$F28:J28) -> 150122.73 | L36: =SUM($F28:L28)-SUMPRODUCT((L$2-$F$2:L$2>=Допущения!$H38)*$F28:L28) -> 164720.6
B37: Машины и оборудование | D37: млн руб. | F37: =SUM($F29:F29)-SUMPRODUCT((F$2-$F$2:F$2>=Допущения!$H39)*$F29:F29) -> 35316 | G37: =SUM($F29:G29)-SUMPRODUCT((G$2-$F$2:G$2>=Допущения!$H39)*$F29:G29) -> 69631.38 | H37: =SUM($F29:H29)-SUMPRODUCT((H$2-$F$2:H$2>=Допущения!$H39)*$F29:H29) -> 102075.01 | I37: =SUM($F29:I29)-SUMPRODUCT((I$2-$F$2:I$2>=Допущения!$H39)*$F29:I29) -> 129068.11 | J37: =SUM($F29:J29)-SUMPRODUCT((J$2-$F$2:J$2>=Допущения!$H39)*$F29:J29) -> 150122.73 | L37: =SUM($F29:L29)-SUMPRODUCT((L$2-$F$2:L$2>=Допущения!$H39)*$F29:L29) -> 129404.6
B38: Холодильное оборудование | D38: млн руб. | F38: =SUM($F30:F30)-SUMPRODUCT((F$2-$F$2:F$2>=Допущения!$H40)*$F30:F30) -> 13080 | G38: =SUM($F30:G30)-SUMPRODUCT((G$2-$F$2:G$2>=Допущения!$H40)*$F30:G30) -> 25789.4 | H38: =SUM($F30:H30)-SUMPRODUCT((H$2-$F$2:H$2>=Допущения!$H40)*$F30:H30) -> 37805.56 | I38: =SUM($F30:I30)-SUMPRODUCT((I$2-$F$2:I$2>=Допущения!$H40)*$F30:I30) -> 47803.005 | J38: =SUM($F30:J30)-SUMPRODUCT((J$2-$F$2:J$2>=Допущения!$H40)*$F30:J30) -> 55601.012 | L38: =SUM($F30:L30)-SUMPRODUCT((L$2-$F$2:L$2>=Допущения!$H40)*$F30:L30) -> 61007.631
B39: Транспортные средства | D39: млн руб. | F39: =SUM($F31:F31)-SUMPRODUCT((F$2-$F$2:F$2>=Допущения!$H41)*$F31:F31) -> 13080 | G39: =SUM($F31:G31)-SUMPRODUCT((G$2-$F$2:G$2>=Допущения!$H41)*$F31:G31) -> 25789.4 | H39: =SUM($F31:H31)-SUMPRODUCT((H$2-$F$2:H$2>=Допущения!$H41)*$F31:H31) -> 37805.56 | I39: =SUM($F31:I31)-SUMPRODUCT((I$2-$F$2:I$2>=Допущения!$H41)*$F31:I31) -> 47803.005 | J39: =SUM($F31:J31)-SUMPRODUCT((J$2-$F$2:J$2>=Допущения!$H41)*$F31:J31) -> 55601.012 | L39: =SUM($F31:L31)-SUMPRODUCT((L$2-$F$2:L$2>=Допущения!$H41)*$F31:L31) -> 61007.631
B40: Прочее | D40: млн руб. | F40: =SUM($F32:F32)-SUMPRODUCT((F$2-$F$2:F$2>=Допущения!$H42)*$F32:F32) -> 20928 | G40: =SUM($F32:G32)-SUMPRODUCT((G$2-$F$2:G$2>=Допущения!$H42)*$F32:G32) -> 41263.04 | H40: =SUM($F32:H32)-SUMPRODUCT((H$2-$F$2:H$2>=Допущения!$H42)*$F32:H32) -> 60488.896 | I40: =SUM($F32:I32)-SUMPRODUCT((I$2-$F$2:I$2>=Допущения!$H42)*$F32:I32) -> 55556.808 | J40: =SUM($F32:J32)-SUMPRODUCT((J$2-$F$2:J$2>=Допущения!$H42)*$F32:J32) -> 47698.58 | L40: =SUM($F32:L32)-SUMPRODUCT((L$2-$F$2:L$2>=Допущения!$H42)*$F32:L32) -> 37123.313
B41: НМА | D41: млн руб. | F41: =SUM($F33:F33)-SUMPRODUCT((F$2-$F$2:F$2>=Допущения!$H44)*$F33:F33) -> 13080 | G41: =SUM($F33:G33)-SUMPRODUCT((G$2-$F$2:G$2>=Допущения!$H44)*$F33:G33) -> 25789.4 | H41: =SUM($F33:H33)-SUMPRODUCT((H$2-$F$2:H$2>=Допущения!$H44)*$F33:H33) -> 37805.56 | I41: =SUM($F33:I33)-SUMPRODUCT((I$2-$F$2:I$2>=Допущения!$H44)*$F33:I33) -> 47803.005 | J41: =SUM($F33:J33)-SUMPRODUCT((J$2-$F$2:J$2>=Допущения!$H44)*$F33:J33) -> 55601.012 | L41: =SUM($F33:L33)-SUMPRODUCT((L$2-$F$2:L$2>=Допущения!$H44)*$F33:L33) -> 61007.631
B43: Амортизация | D43: млн руб. | F43: =SUM(F44:F49) -> 20339.4 | G43: =SUM(G44:G49) -> 40102.517 | H43: =SUM(H44:H49) -> 58787.646 | I43: =SUM(I44:I49) -> 67357.673 | J43: =SUM(J44:J49) -> 72705.227 | L43: =SUM(L44:L49) -> 67640.7
B44: Здания | D44: млн руб. | F44: =F36/Допущения!$H38 -> 1177.2 | G44: =G36/Допущения!$H38 -> 2321.046 | H44: =H36/Допущения!$H38 -> 3402.5004 | I44: =I36/Допущения!$H38 -> 4302.2705 | J44: =J36/Допущения!$H38 -> 5004.0911 | L44: =L36/Допущения!$H38 -> 5490.6868
B45: Машины и оборудование | D45: млн руб. | F45: =F37/Допущения!$H39 -> 7063.2 | G45: =G37/Допущения!$H39 -> 13926.276 | H45: =H37/Допущения!$H39 -> 20415.002 | I45: =I37/Допущения!$H39 -> 25813.623 | J45: =J37/Допущения!$H39 -> 30024.547 | L45: =L37/Допущения!$H39 -> 25880.921
B46: Холодильное оборудование | D46: млн руб. | F46: =F38/Допущения!$H40 -> 1635 | G46: =G38/Допущения!$H40 -> 3223.675 | H46: =H38/Допущения!$H40 -> 4725.695 | I46: =I38/Допущения!$H40 -> 5975.3756 | J46: =J38/Допущения!$H40 -> 6950.1265 | L46: =L38/Допущения!$H40 -> 7625.9538
B47: Транспортные средства | D47: млн руб. | F47: =F39/Допущения!$H41 -> 2180 | G47: =G39/Допущения!$H41 -> 4298.2333 | H47: =H39/Допущения!$H41 -> 6300.9267 | I47: =I39/Допущения!$H41 -> 7967.1675 | J47: =J39/Допущения!$H41 -> 9266.8354 | L47: =L39/Допущения!$H41 -> 10167.938
B48: Прочее | D48: млн руб. | F48: =F40/Допущения!$H42 -> 6976 | G48: =G40/Допущения!$H42 -> 13754.347 | H48: =H40/Допущения!$H42 -> 20162.965 | I48: =I40/Допущения!$H42 -> 18518.936 | J48: =J40/Допущения!$H42 -> 15899.527 | L48: =L40/Допущения!$H42 -> 12374.438
B49: НМА | D49: млн руб. | F49: =F41/Допущения!$H44 -> 1308 | G49: =G41/Допущения!$H44 -> 2578.94 | H49: =H41/Допущения!$H44 -> 3780.556 | I49: =I41/Допущения!$H44 -> 4780.3005 | J49: =J41/Допущения!$H44 -> 5560.1012 | L49: =L41/Допущения!$H44 -> 6100.7631
B51: Остаточная стоимость | D51: млн руб. | F51: =SUM(F52:F57) -> 110460.6 | G51: =SUM(G52:G57) -> 197452.08 | H51: =SUM(H52:H57) -> 258826.04 | I51: =SUM(I52:I57) -> 291442.82 | J51: =SUM(J52:J57) -> 296717.66 | L51: =SUM(L52:L57) -> 283143.14
B52: Здания | D52: млн руб. | F52: =E52+F28-F44 -> 34138.8 | G52: =F52+G28-G44 -> 66133.134 | H52: =G52+H28-H44 -> 95174.266 | I52: =H52+I28-I44 -> 117865.1 | J52: =I52+J28-J44 -> 133915.63 | L52: =J52+L28-L44 -> 143022.81
...

Sheet Итоги
B2: ПАО "КАМАЗ"
B4: Прогноз до 2025 года
B5: Суммы в млн руб. (если не указано иное)
B7: Доходы и расходы | C7: 2023 | D7: 2024 | E7: 2025 | F7: 2026 | G7: 2027 | H7: 2028 | J7: 2029
B8: Выручка | C8: =Расчет!E91 -> 3145859 | D8: =ROUND(Расчет!F91,0) -> 3703450 | E8: =ROUND(Расчет!G91,0) -> 4258967 | F8: =ROUND(Расчет!H91,0) -> 4684864 | G8: =ROUND(Расчет!I91,0) -> 5012805 | H8: =ROUND(Расчет!J91,0) -> 5263445 | J8: =ROUND(Расчет!L91,0) -> 5421348
B9: EBITDA | C9: =Расчет!E104 -> 344829 | D9: =ROUND(Расчет!F104,0) -> 381528 | E9: =ROUND(Расчет!G104,0) -> 401199 | F9: =ROUND(Расчет!H104,0) -> 412123 | G9: =ROUND(Расчет!I104,0) -> 408482 | H9: =ROUND(Расчет!J104,0) -> 393428 | J9: =ROUND(Расчет!L104,0) -> 367227
B10: Прибыль | C10: =Расчет!E119 -> 78611 | D10: =ROUND(Расчет!F119,0) -> 97507 | E10: =ROUND(Расчет!G119,0) -> 85363 | F10: =ROUND(Расчет!H119,0) -> 86374 | G10: =ROUND(Расчет!I119,0) -> 109035 | H10: =ROUND(Расчет!J119,0) -> 102708 | J10: =ROUND(Расчет!L119,0) -> 90407
B13: Денежные потоки | C13: 2023 | D13: 2024 | E13: 2025 | F13: 2026 | G13: 2027 | H13: 2028 | J13: 2029
B14: Операционная деятельность | C14: =Расчет!E135 -> 270279 | D14: =ROUND(Расчет!F135,0) -> 180099 | E14: =ROUND(Расчет!G135,0) -> 198343 | F14: =ROUND(Расчет!H135,0) -> 211024 | G14: =ROUND(Расчет!I135,0) -> 209025 | H14: =ROUND(Расчет!J135,0) -> 201503 | J14: =ROUND(Расчет!L135,0) -> 181573
B15: Инвестиции | C15: =Расчет!E139 -> -194255 | D15: =ROUND(Расчет!F139,0) -> -135760 | E15: =ROUND(Расчет!G139,0) -> -131569 | F15: =ROUND(Расчет!H139,0) -> -125122 | G15: =ROUND(Расчет!I139,0) -> -105151 | H15: =ROUND(Расчет!J139,0) -> -83372 | J15: =ROUND(Расчет!L139,0) -> -59997
B16: Кредиты и облигации | C16: =Расчет!E147 -> -78694 | D16: =ROUND(Расчет!F147,0) -> -107193 | E16: =ROUND(Расчет!G147,0) -> -96705 | F16: =ROUND(Расчет!H147,0) -> -108006 | G16: =ROUND(Расчет!I147,0) -> -116812 | H16: =ROUND(Расчет!J147,0) -> -123432 | J16: =ROUND(Расчет!L147,0) -> -125739
B17: Итого CF | C17: =SUM(C14:C16) -> -2670 | D17: =SUM(D14:D16) -> -62854 | E17: =SUM(E14:E16) -> -29931 | F17: =SUM(F14:F16) -> -22104 | G17: =SUM(G14:G16) -> -12938 | H17: =SUM(H14:H16) -> -5301 | J17: =SUM(J14:J16) -> -4163
B18: Остаток денежных средств | C18: =Расчет!E152 -> 39104 | D18: =Расчет!F152 -> -23750.654 | E18: =Расчет!G152 -> -53681.392 | F18: =Расчет!H152 -> -75784.529 | G18: =Расчет!I152 -> -88721.659 | H18: =Расчет!J152 -> -94022.498 | J18: =Расчет!L152 -> -98185.571
B21: Баланс | C21: 2023 | D21: 2024 | E21: 2025 | F21: 2026 | G21: 2027 | H21: 2028 | J21: 2029
B22: Основные средства и НМА | C22: =Расчет!E157+Расчет!E159 -> 526654 | D22: =Расчет!F157+Расчет!F159 -> 541142.33 | E22: =Расчет!G157+Расчет!G159 -> 532161.54 | F22: =Расчет!H157+Расчет!H159 -> 511641.22 | G22: =Расчет!I157+Расчет!I159 -> 500176.73 | H22: =Расчет!J157+Расчет!J159 -> 471557.8 | J22: =Расчет!L157+Расчет!L159 -> 431319.71
B23: Дебиторская задолженность и прочие активы | C23: =Расчет!E160+Расчет!E161+Расчет!E164 -> 211234 | D23: =Расчет!F160+Расчет!F161+Расчет!F164 -> 214557.52 | E23: =Расчет!G160+Расчет!G161+Расчет!G164 -> 216972.61 | F23: =Расчет!H160+Расчет!H161+Расчет!H164 -> 218679.28 | G23: =Расчет!I160+Расчет!I161+Расчет!I164 -> 220454.21 | H23: =Расчет!J160+Расчет!J161+Расчет!J164 -> 222300.13 | J23: =Расчет!L160+Расчет!L161+Расчет!L164 -> 224219.9
B24: Запасы | C24: =Расчет!E162 -> 236826 | D24: =Расчет!F162 -> 278802.45 | E24: =Расчет!G162 -> 320622.82 | F24: =Расчет!H162 -> 352685.11 | G24: =Расчет!I162 -> 377373.06 | H24: =Расчет!J162 -> 396241.72 | J24: =Расчет!L162 -> 408128.97
B25: Денежные средства | C25: =Расчет!E163 -> 39104 | D25: =Расчет!F163 -> -23750.654 | E25: =Расчет!G163 -> -53681.392 | F25: =Расчет!H163 -> -75784.529 | G25: =Расчет!I163 -> -88721.659 | H25: =Расчет!J163 -> -94022.498 | J25: =Расчет!L163 -> -98185.571
B26: Актив | C26: =SUM(C22:C25) -> 1013818 | D26: =SUM(D22:D25) -> 1010751.6 | E26: =SUM(E22:E25) -> 1016075.6 | F26: =SUM(F22:F25) -> 1007221.1 | G26: =SUM(G22:G25) -> 1009282.3 | H26: =SUM(H22:H25) -> 996077.15 | J26: =SUM(J22:J25) -> 965483.01
B28: Капитал | C28: =Расчет!E170 -> 217579 | D28: =Расчет!F170 -> 315053.07 | E28: =Расчет!G170 -> 400383.27 | F28: =Расчет!H170 -> 486724.37 | G28: =Расчет!I170 -> 595726.43 | H28: =Расчет!J170 -> 698401.23 | J28: =Расчет!L170 -> 788775.49
B29: Долг | C29: =Расчет!E172 -> 228255 | D29: =Расчет!F172 -> 220098.74 | E29: =Расчет!G172 -> 232644.85 | F29: =Расчет!H172 -> 242263.53 | G29: =Расчет!I172 -> 249669.92 | H29: =Расчет!J172 -> 255330.51 | J29: =Расчет!L172 -> 258896.69
B30: Кредиторская задолженность и прочие об-ва | C30: =Расчет!E174+Расчет!E175 -> 473485 | D30: =Расчет!F174+Расчет!F175 -> 479687.98 | E30: =Расчет!G174+Расчет!G175 -> 495936.5 | F30: =Расчет!H174+Расчет!H175 -> 508296.4 | G30: =Расчет!I174+Расчет!I175 -> 517717.62 | H30: =Расчет!J174+Расчет!J175 -> 524819.82 | J30: =Расчет!L174+Расчет!L175 -> 529139.92
B31: Пассив | C31: =SUM(C28:C30) -> 919319 | D31: =SUM(D28:D30) -> 1014839.8 | E31: =SUM(E28:E30) -> 1128964.6 | F31: =SUM(F28:F30) -> 1237284.3 | G31: =SUM(G28:G30) -> 1363114 | H31: =SUM(H28:H30) -> 1478551.6 | J31: =SUM(J28:J30) -> 1576812.1
B34: Ключевые показатели | C34: 2023 | D34: 2024 | E34: 2025 | F34: 2026 | G34: 2027 | H34: 2028 | J34: 2029
B35: FCFE | C35: =Расчет!E135+Расчет!E139+Расчет!E141+Расчет!E142 -> 67611 | D35: =Расчет!F135+Расчет!F139+Расчет!F141+Расчет!F142 -> 36182.481 | E35: =Расчет!G135+Расчет!G139+Расчет!G141+Расчет!G142 -> 79320.159 | F35: =Расчет!H135+Расчет!H139+Расчет!H141+Расчет!H142 -> 95521.063 | G35: =Расчет!I135+Расчет!I139+Расчет!I141+Расчет!I142 -> 111281.26 | H35: =Расчет!J135+Расчет!J139+Расчет!J141+Расчет!J142 -> 123791.94 | J35: =Расчет!L135+Расчет!L139+Расчет!L141+Расчет!L142 -> 125141.62
B36: FCFF | C36: =Расчет!E135+Расчет!E139-Расчет!E110*(1-Допущения!E23) -> 139621.6 | D36: =Расчет!F135+Расчет!F139-Расчет!F110*(1-Допущения!F23) -> 159729.25 | E36: =Расчет!G135+Расчет!G139-Расчет!G110*(1-Допущения!G23) -> 187269.77 | F36: =Расчет!H135+Расчет!H139-Расчет!H110*(1-Допущения!H23) -> 207559.12 | G36: =Расчет!I135+Расчет!I139-Расчет!I110*(1-Допущения!I23) -> 222270.67 | H36: =Расчет!J135+Расчет!J139-Расчет!J110*(1-Допущения!J23) -> 237024.44 | J36: =Расчет!L135+Расчет!L139-Расчет!L110*(1-Допущения!L23) -> 241000.34
B37: Капитал/Активы | C37: =C28/C26 -> 0.21461347 | D37: =D28/D26 -> 0.31170176 | E37: =E28/E26 -> 0.39404871 | F37: =F28/F26 -> 0.4832349 | G37: =G28/G26 -> 0.59024755 | H37: =H28/H26 -> 0.70115173 | J37: =J28/J26 -> 0.81697501
B38: Чистый долг/EBITDA | C38: =(C29-C25)/C9 -> 0.54853565 | D38: =(D29-D25)/D9 -> 0.63913891 | E38: =(E29-E25)/E9 -> 0.71367635 | F38: =(F29-F25)/F9 -> 0.77173092 | G38: =(G29-G25)/G9 -> 0.82841246 | H38: =(H29-H25)/H9 -> 0.88797191 | J38: =(J29-J25)/J9 -> 0.97237475
B39: EBITDA/Проценты | C39: =-Расчет!E104/Расчет!E110 -> 4.3376354 | D39: =-Расчет!F104/Расчет!F110 -> 2.645129 | E39: =-Расчет!G104/Расчет!G110 -> 2.6636543 | F39: =-Расчет!H104/Расчет!H110 -> 2.7100687 | G39: =-Расчет!I104/Расчет!I110 -> 2.7601119 | H39: =-Расчет!J104/Расчет!J110 -> 2.647272 | J39: =-Расчет!L104/Расчет!L110 -> 2.4599663
B40: Net margin | C40: =C10/C8 -> 0.024988723 | D40: =D10/D8 -> 0.026328694 | E40: =E10/E8 -> 0.020043123 | F40: =F10/F8 -> 0.018436821 | G40: =G10/G8 -> 0.021751295 | H40: =H10/H8 -> 0.019513456 | J40: =J10/J8 -> 0.016676111
B41: ROE | C41: =C10/C28 -> 0.36129865 | D41: =D10/AVERAGE(C28:D28) -> 0.36613266 | E41: =E10/AVERAGE(D28:E28) -> 0.23863199 | F41: =F10/AVERAGE(E28:F28) -> 0.19473172 | G41: =G10/AVERAGE(F28:G28) -> 0.2014595 | H41: =H10/AVERAGE(G28:H28) -> 0.15872932 | J41: =J10/AVERAGE(H28:J28) -> 0.12158205
B42: ROA | C42: =C10/C26 -> 0.077539558 | D42: =D10/AVERAGE(C26:D26) -> 0.09632368 | E42: =E10/AVERAGE(D26:E26) -> 0.084233129 | F42: =F10/AVERAGE(E26:F26) -> 0.085379472 | G42: =G10/AVERAGE(F26:G26) -> 0.10814264 | H42: =H10/AVERAGE(G26:H26) -> 0.1024335 | J42: =J10/AVERAGE(H26:J26) -> 0.092178666
B45: Для презентации
B46: Накопленная прибыль | C46: =Расчет!E169/1000 -> 215.277 | D46: =Расчет!F169/1000 -> 312.75107 | E46: =Расчет!G169/1000 -> 398.08127 | F46: =Расчет!H169/1000 -> 484.42237 | G46: =Расчет!I169/1000 -> 593.42443 | H46: =Расчет!J169/1000 -> 696.09923 | J46: =Расчет!L169/1000 -> 786.47349
B47: Свободные денежные средства | C47: =C25/1000 -> 39.104 | D47: =D25/1000 -> -23.750654 | E47: =E25/1000 -> -53.681392 | F47: =F25/1000 -> -75.784529 | G47: =G25/1000 -> -88.721659 | H47: =H25/1000 -> -94.022498 | J47: =J25/1000 -> -98.185571
B50: EBITDA | C50: =ROUND(Расчет!E104/1000,0) -> 345 | D50: =ROUND(Расчет!F104/1000,0) -> 382 | E50: =ROUND(Расчет!G104/1000,0) -> 401 | F50: =ROUND(Расчет!H104/1000,0) -> 412 | G50: =ROUND(Расчет!I104/1000,0) -> 408 | H50: =ROUND(Расчет!J104/1000,0) -> 393 | J50: =ROUND(Расчет!L104/1000,0) -> 367
B51: Управленческие и прочие расходы | C51: =ROUND((-Расчет!E100-Расчет!E95-Расчет!E101)/1000,0) -> 549 | D51: =ROUND((-Расчет!F100-Расчет!F95-Расчет!F101)/1000,0) -> 660 | E51: =ROUND((-Расчет!G100-Расчет!G95-Расчет!G101)/1000,0) -> 773 | F51: =ROUND((-Расчет!H100-Расчет!H95-Расчет!H101)/1000,0) -> 861 | G51: =ROUND((-Расчет!I100-Расчет!I95-Расчет!I101)/1000,0) -> 933 | H51: =ROUND((-Расчет!J100-Расчет!J95-Расчет!J101)/1000,0) -> 993 | J51: =ROUND((-Расчет!L100-Расчет!L95-Расчет!L101)/1000,0) -> 1037
B52: Персонал | C52: =ROUND((-Расчет!E94-Расчет!E99)/1000,0) -> 457 | D52: =ROUND((-Расчет!F94-Расчет!F99)/1000,0) -> 565 | E52: =ROUND((-Расчет!G94-Расчет!G99)/1000,0) -> 673 | F52: =ROUND((-Расчет!H94-Расчет!H99)/1000,0) -> 759 | G52: =ROUND((-Расчет!I94-Расчет!I99)/1000,0) -> 832 | H52: =ROUND((-Расчет!J94-Расчет!J99)/1000,0) -> 896 | J52: =ROUND((-Расчет!L94-Расчет!L99)/1000,0) -> 947
B53: ТМЦ | C53: =ROUND(-Расчет!E93/1000,0) -> 1795 | D53: =ROUND(-Расчет!F93/1000,0) -> 2097 | E53: =ROUND(-Расчет!G93/1000,0) -> 2412 | F53: =ROUND(-Расчет!H93/1000,0) -> 2653 | G53: =ROUND(-Расчет!I93/1000,0) -> 2839 | H53: =ROUND(-Расчет!J93/1000,0) -> 2980 | J53: =ROUND(-Расчет!L93/1000,0) -> 3070
C54: =ROUND(Расчет!E22/1000,0) -> 3139 | D54: =ROUND(Расчет!F22/1000,0) -> 3703 | E54: =ROUND(Расчет!G22/1000,0) -> 4259 | F54: =ROUND(Расчет!H22/1000,0) -> 4685 | G54: =ROUND(Расчет!I22/1000,0) -> 5013 | H54: =ROUND(Расчет!J22/1000,0) -> 5263 | J54: =ROUND(Расчет!L22/1000,0) -> 5421
...

Sheet Оценка
B2: Итоги
B3: Метод | C3: EV | D3: Equity | E3: Net Debt | F3: руб./акцию | G3: Вес
B4: Доходный (FCFF) | C4: =C27 -> 1563641.3 | D4: =C4-E4 -> 1374490.3 | E4: =$E$17 -> 189151 | F4: =D4/$K$33 -> 5060.7154 | G4: 0.3
B5: Сравнительный | C5: =MEDIAN(J41:K41) -> 1329286 | D5: =C5-E5 -> 1140135 | E5: =$E$17 -> 189151 | F5: =D5/$K$33 -> 4197.8459 | G5: 0.5
B6: Затратный | C6: =D6+E6 -> 406730 | D6: =Расчет!E165-Расчет!E176 -> 217579 | E6: =$E$17 -> 189151 | F6: =D6/$K$33 -> 801.10088 | G6: 0.2
B7: Итоговая стоимость | C7: =C6*G6+C4*G4+C5*G5 -> 1215081.4 | D7: =C7-E7 -> 1025930.4 | E7: =E6 -> 189151 | F7: =D7/$K$33 -> 3777.3578 | G7: =SUM(G4:G6) -> 1
B9: Доходный метод
D11: Ед. изм.
B12: Ежегодный прирост | D12: % | E12: ='Анализ чувствительности'!G5 -> 0.03
B13: WACC | D13: % | E13: =(E14+E16*(E15-E14))*C18+(Допущения!E22*C17)*(1-Допущения!L23) -> 0.15668473
B14: Доходность российских облигаций | D14: % | E14: 0.037
B15: Биржевая доходность | D15: % | E15: =(14.8%+21.8%)/2 -> 0.183
B16: Бета | D16: х | E16: 0.9
B17: Долг | C17: =E17/SUM($E$17:$E$18) -> 0.24205101 | D17: млн руб. | E17: =Расчет!E172-Расчет!E163 -> 189151
B18: Капитализация | C18: =E18/SUM($E$17:$E$18) -> 0.75794899 | D18: млн руб. | E18: 592300
F19: =E18+E17 -> 781451
B21: Денежные потоки | C21: 2023 | D21: 2024 | E21: 2025 | F21: 2026 | G21: 2027 | H21: 2028 | J21: 2029
B22: FCFF | C22: =Итоги!C36 -> 139621.6 | D22: =Итоги!D36 -> 159729.25 | E22: =Итоги!E36 -> 187269.77 | F22: =Итоги!F36 -> 207559.12 | G22: =Итоги!G36 -> 222270.67 | H22: =Итоги!H36 -> 237024.44 | J22: =Итоги!J36 -> 241000.34
B23: Терминальная стоимость | H23: =J22*(1-E12)/(E13-E12) -> 1845292.1
B24: Период дисконтирования | C24: =C21-2023+0.5 -> 0.5 | D24: =D21-2023+0.5 -> 1.5 | E24: =E21-2023+0.5 -> 2.5 | F24: =F21-2023+0.5 -> 3.5 | G24: =G21-2023+0.5 -> 4.5 | H24: =H21-2023+0.5 -> 5.5
B25: Дисконтированный поток | C25: =C22/(1+'Анализ чувствительности'!$G$4)^(C24) -> 129821.05 | D25: =D22/(1+'Анализ чувствительности'!$G$4)^(D24) -> 128399.09 | E25: =E22/(1+'Анализ чувствительности'!$G$4)^(E24) -> 130145.81 | F25: =F22/(1+'Анализ чувствительности'!$G$4)^(F24) -> 124706.56 | G25: =G22/(1+'Анализ чувствительности'!$G$4)^(G24) -> 115455.51 | H25: =H22/(1+'Анализ чувствительности'!$G$4)^(H24) -> 106441.41
H26: =H23/(1+'Анализ чувствительности'!$G$4)^(H24) -> 828671.89
B27: EV | C27: =SUM(C25:H26) -> 1563641.3
B30: Сравнительный метод
B32: Компания | D32: Ед. изм. | E32: EBITDA | F32: Выручка | G32: EV | H32: Капиталтизация | I32: Число магазинов | J32: Торговая площадь | K32: Число акций, млн
B33: X5 Retail Group | D33: млн руб. | E33: =Расчет!E104 -> 344829 | F33: =Расчет!E22 -> 3138516.8 | H33: =E18 -> 592300 | I33: 27015 | J33: 10206 | K33: 271.6
B34: Магнит | D34: млн руб. | E34: 166000 | F34: 2545000 | G34: 876400 | H34: 712200 | I34: 29165 | J34: 10053 | K34: 101.9
B35: Лента | D35: млн руб. | E35: 33600 | F35: 615900 | G35: 173100 | H35: 77800 | I35: 2819 | J35: 2325 | K35: 116
B36: Окей | D36: млн руб. | E36: 8900 | F36: 207900 | G36: 43600 | H36: 8030 | I36: 297 | J36: 664 | K36: 269.1
B40: Компания | D40: Ед. изм. | E40: Стоимость акции | F40: Выручка на 1000 м3 | G40: EBITDA на 1000 м2 | H40: EV/EBITDA | I40: EV/Sales | J40: EV 1 | K40: EV 2
B41: X5 Retail Group | D41: млн руб. | E41: =H33/K33 -> 2180.7806 | F41: =F33/J33 -> 307.51683 | G41: =E33/J33 -> 33.78689 | H41: =MEDIAN(H42:H44) -> 5.1517857 | I41: =MEDIAN(I42:I44) -> 0.28105212 | J41: =H41*E33 -> 1776485.1 | K41: =I41*F33 -> 882086.8
B42: Магнит | D42: млн руб. | E42: =H34/K34 -> 6989.2051 | F42: =F34/J34 -> 253.15826 | G42: =E34/J34 -> 16.512484 | H42: =G34/E34 -> 5.2795181 | I42: =G34/F34 -> 0.34436149
B43: Лента | D43: млн руб. | E43: =H35/K35 -> 670.68966 | F43: =F35/J35 -> 264.90323 | G43: =E35/J35 -> 14.451613 | H43: =G35/E35 -> 5.1517857 | I43: =G35/F35 -> 0.28105212
B44: Окей | D44: млн руб. | E44: =H36/K36 -> 29.840208 | F44: =F36/J36 -> 313.10241 | G44: =E36/J36 -> 13.403614 | H44: =G36/E36 -> 4.8988764 | I44: =G36/F36 -> 0.20971621

Sheet Анализ чувствительности
C1: Анализ чувствительности
C2: Суммы в млрд руб. (если не указано иное)
C4: WACC | G4: =Оценка!E13 -> 0.15668473
C5: Постпрогнозный рост | G5: 0.03
C6: Equity | G6: =Оценка!D4/1000 -> 1374.4903
H8: WACC
B9: =G6 -> 1374.4903 | C9: =D9-0.2% -> 0.147 | D9: =E9-0.2% -> 0.149 | E9: =F9-0.2% -> 0.151 | F9: =G9-0.2% -> 0.153 | G9: =H9-0.2% -> 0.155 | H9: 0.157 | I9: =H9+0.002 -> 0.159 | J9: =I9+0.002 -> 0.161 | K9: =J9+0.002 -> 0.163 | L9: =K9+0.002 -> 0.165 | M9: =L9+0.002 -> 0.167
B10: =B11-0.002 -> 0.02 | C10: 1376.6641 | D10: 1365.1036 | E10: 1353.6624 | F10: 1342.3392 | G10: 1331.1326 | H10: 1320.041 | I10: 1309.063 | J10: 1298.1973 | K10: 1287.4424 | L10: 1276.7971 | M10: 1266.2599
B11: =B12-0.002 -> 0.022 | C11: 1387.049 | D11: 1375.3894 | E11: 1363.8503 | F11: 1352.4303 | G11: 1341.1279 | H11: 1329.9417 | I11: 1318.8701 | J11: 1307.9118 | K11: 1297.0654 | L11: 1286.3295 | M11: 1275.7029
A12: Постпрогнозный рост | B12: =B13-0.002 -> 0.024 | C12: 1397.7469 | D12: 1385.9853 | E12: 1374.3454 | F12: 1362.8256 | G12: 1351.4246 | H12: 1340.1408 | I12: 1328.9728 | J12: 1317.9192 | K12: 1306.9785 | L12: 1296.1494 | M12: 1285.4305
B13: =B14-0.002 -> 0.026 | C13: 1408.7723 | D13: 1396.9055 | E13: 1385.1616 | F13: 1373.5391 | G13: 1362.0365 | H13: 1350.6522 | I13: 1339.3848 | J13: 1328.2329 | K13: 1317.195 | L13: 1306.2699 | M13: 1295.4559
B14: =B15-0.002 -> 0.028 | C14: 1420.1404 | D14: 1408.1652 | E14: 1396.3141 | F14: 1384.5856 | G14: 1372.9782 | H14: 1361.4902 | I14: 1350.1204 | J14: 1338.8672 | K14: 1327.7291 | L14: 1316.7049 | M14: 1305.793
B15: 0.03 | C15: 1431.8674 | D15: 1419.7804 | E15: 1407.8187 | F15: 1395.9809 | G15: 1384.2653 | H15: 1372.6705 | I15: 1361.195 | J15: 1349.8372 | K15: 1338.5959 | L15: 1327.4694 | M15: 1316.4564
B16: =B15+0.002 -> 0.032 | C16: 1443.9706 | D16: 1431.7682 | E16: 1419.6924 | F16: 1407.7418 | G16: 1395.9146 | H16: 1384.2095 | I16: 1372.6249 | J16: 1361.1592 | K16: 1349.8112 | L16: 1338.5792 | M16: 1327.4619
B17: =B16+0.002 -> 0.034 | C17: 1456.4684 | D17: 1444.1468 | E17: 1431.9532 | F17: 1419.8861 | G17: 1407.9437 | H17: 1396.1247 | I17: 1384.4274 | J17: 1372.8504 | K17: 1361.3922 | L17: 1350.0513 | M17: 1338.8262
B18: =B17+0.002 -> 0.036 | C18: 1469.3805 | D18: 1456.9358 | E18: 1444.6204 | F18: 1432.4329 | G18: 1420.3715 | H18: 1408.4348 | I18: 1396.6211 | J18: 1384.929 | K18: 1373.357 | L18: 1361.9035 | M18: 1350.5672
B19: =B18+0.002 -> 0.038 | C19: 1482.7278 | D19: 1470.1558 | E19: 1457.7146 | F19: 1445.4026 | G19: 1433.2181 | H19: 1421.1597 | I19: 1409.2258 | J19: 1397.4147 | K19: 1385.725 | L19: 1374.1553 | M19: 1362.7039
B20: =B19+0.002 -> 0.04 | C20: 1496.5326 | D20: 1483.8289 | E20: 1471.2575 | F20: 1458.8168 | G20: 1446.5052 | H20: 1434.3209 | I20: 1422.2625 | J20: 1410.3284 | K20: 1398.5171 | L20: 1386.827 | M20: 1375.2567
